<?xml version="1.0"?>

<robot name="go1" xmlns:xacro="http://www.ros.org/wiki/xacro">

    <!-- if I set default to true it will jiggle around on the floor -->
    <xacro:arg name="DEBUG" default="false"/>

    <xacro:include filename="$(find unigo1)/xacro/inertial_macros.xacro" />
    <xacro:include filename="$(find unigo1)/xacro/const.xacro"/>
    <xacro:include filename="$(find unigo1)/xacro/materials.xacro"/>
    <xacro:include filename="$(find unigo1)/xacro/leg.xacro"/>
    <!-- <xacro:include filename="$(find unigo1)/xacro/stairs.xacro"/> -->
    <xacro:include filename="$(find unigo1)/xacro/gazebo.xacro"/>
    <xacro:include filename="$(find unigo1)/xacro/depthCamera1.xacro"/>
<!--    <xacro:include filename="$(find unigo1)/xacro/ultraSound.xacro"/>-->
    <!-- <xacro:include filename="$(find go1_gazebo)/launch/stairs.urdf.xacro"/> -->

    <!-- <xacro:stairs stairs="15" xpos="0" ypos="0" zpos="0" /> -->

    <!-- Rotor related joint and link is only for demonstrate location. -->
    <!-- Actually, the rotor will rotate and the joint is not fixed. Reduction ratio should be considered. -->

    <!-- Debug mode will hung up the robot, use "true" or "false" to switch it. -->
    <xacro:if value="$(arg DEBUG)">
        <link name="world"/>
        <joint name="base_static_joint" type="fixed">
            <origin rpy="0 0 0" xyz="0 0 0"/>
            <parent link="world"/>
            <child link="base_link"/><!-- was "base"-->
        </joint>
    </xacro:if> 


    <link name="base_link"><!-- was "base", needs to be called base_link for Nav2, or remap Nav2 commands -->
        <visual>
            <origin rpy="0 0 0" xyz="0 0 0"/>
            <geometry>
                <box size="0.001 0.001 0.001"/>
            </geometry>
        </visual>
    </link>

    <!-- base footprint for use with RTABMAP -->
    <!-- !!! this conflicts with other things, it does not work !!!-->
    <!--
    <joint name="base_footprint_joint" type="fixed">
        <parent link="base_link"/>
        <child link="base_footprint"/>
        <origin xyz="0 0 0" rpy="0 0 0"/>
    </joint>

    <link name="base_footprint">
    </link>
    -->
    <!---->

    <joint name="floating_base" type="fixed">
        <origin rpy="0 0 0" xyz="0 0 0.35"/><!-- z value set to 0.35 so robot floats in the air, should be set to 0 if controlling with legs-->
        <parent link="base_link"/><!-- was "base"-->
        <child link="trunk"/>
    </joint>

    <link name="trunk">
        <visual>
            <origin rpy="0 0 0" xyz="0 0 0"/>
            <geometry>
                <mesh filename="file://$(find unigo1)/meshes/trunk.dae" scale="1 1 1"/>
                <!-- filename="package://unigo1/meshes/trunk.dae" works for Rviz2 but not Gazebo-->
            </geometry>
            <!-- <material name="orange"/> -->
        </visual>
        <collision>
            <origin rpy="0 0 0" xyz="0 0 0"/>
            <geometry>
                <box size="${trunk_length} ${trunk_width} ${trunk_height}"/>
            </geometry>
        </collision>
        <inertial>
            <origin rpy="0 0 0" xyz="${trunk_com_x} ${trunk_com_y} ${trunk_com_z}"/>
            <mass value="${trunk_mass}"/>
            <inertia
                ixx="${trunk_ixx}" ixy="${trunk_ixy}" ixz="${trunk_ixz}"
                iyy="${trunk_iyy}" iyz="${trunk_iyz}"
                izz="${trunk_izz}"/>  
        </inertial>
    </link>

    <!-- ADDED START -->
    <!-- until high level control is implemented we use a differential drive to control the robot for simulation -->
    <!-- remove this whole section (from ADDED START to ADDED END) once high-level leg control is established -->
    
        <!-- LEFT WHEEL -->

    <joint name="left_wheel_joint" type="continuous">
        <parent link="base_link"/><!-- was "base"-->
        <child link="left_wheel"/>
        <origin xyz="0 0.175 0" rpy="-${pi/2} 0 0"/>
        <axis xyz="0 0 1"/>
    </joint>

    <link name="left_wheel">
        <visual>
            <geometry>
                <cylinder length="0.04" radius="0.05" />
            </geometry>
            <material name="blue"/>
        </visual>
        <collision>
            <geometry>
                <cylinder length="0.04" radius="0.05" />
            </geometry>
        </collision>
        <xacro:inertial_cylinder mass="0.1" length="0.05" radius="0.05">
            <origin xyz="0 0 0" rpy="0 0 0"/>
        </xacro:inertial_cylinder>
    </link>

    <gazebo reference="left_wheel">
        <material>Gazebo/Blue</material>
    </gazebo>

        <!-- RIGHT WHEEL -->

    <joint name="right_wheel_joint" type="continuous">
        <parent link="base_link"/><!-- was "base"-->
        <child link="right_wheel"/>
        <origin xyz="0 -0.175 0" rpy="${pi/2} 0 0"/>
        <axis xyz="0 0 -1"/>
    </joint>

    <link name="right_wheel">
        <visual>
            <geometry>
                <cylinder length="0.04" radius="0.05" />
            </geometry>
            <material name="blue"/>
        </visual>
        <collision>
            <geometry>
                <cylinder length="0.04" radius="0.05" />
            </geometry>
        </collision>
        <xacro:inertial_cylinder mass="0.1" length="0.05" radius="0.05">
            <origin xyz="0 0 0" rpy="0 0 0"/>
        </xacro:inertial_cylinder>
    </link>

    <gazebo reference="right_wheel">
        <material>Gazebo/Blue</material>
    </gazebo>

        <!-- FRONT BALL -->
    
    <joint name="front_ball_joint" type="fixed">
        <parent link="trunk"/>
        <child link="front_ball"/>
        <origin xyz="0.3 0 -0.35" rpy="0 0 0"/>
    </joint>

    <link name="front_ball">
        <visual>
            <geometry>
                <sphere radius="0.05" />
            </geometry>
            <material name="blue"/>
        </visual>
        <collision>
            <geometry>
                <sphere radius="0.05" />
            </geometry>
        </collision>
        <xacro:inertial_sphere mass="0.1" radius="0.05">
            <origin xyz="0 0 0" rpy="0 0 0"/>
        </xacro:inertial_sphere>
    </link>

    <gazebo reference="front_ball">
        <material>Gazebo/Blue</material>
    </gazebo>

    <gazebo reference="front_ball">
        <material>Gazebo/Black</material>
        <mu1 value="0.001"/>
        <mu2 value="0.001"/>
    </gazebo>    

        <!-- BACK BALL -->

    <joint name="back_ball_joint" type="fixed">
        <parent link="trunk"/>
        <child link="back_ball"/>
        <origin xyz="-0.3 0 -0.35" rpy="0 0 0"/>
    </joint>

    <link name="back_ball">
        <visual>
            <geometry>
                <sphere radius="0.05" />
            </geometry>
            <material name="blue"/>
        </visual>
        <collision>
            <geometry>
                <sphere radius="0.05" />
            </geometry>
        </collision>
        <xacro:inertial_sphere mass="0.1" radius="0.05">
            <origin xyz="0 0 0" rpy="0 0 0"/>
        </xacro:inertial_sphere>
    </link>

    <gazebo reference="back_ball">
        <material>Gazebo/Blue</material>
    </gazebo>

    <gazebo reference="back_ball">
        <material>Gazebo/Black</material>
        <mu1 value="0.001"/>
        <mu2 value="0.001"/>
    </gazebo>    


    <!-- ADDED END -->

    <joint name="imu_joint" type="fixed">
        <parent link="trunk"/>
        <child link="imu_link"/>
        <origin rpy="0 0 0" xyz="-0.01592 -0.06659 -0.00617"/>
    </joint>

    <link name="imu_link">
        <inertial>
            <mass value="0.001"/>
            <origin rpy="0 0 0" xyz="0 0 0"/>
            <inertia ixx="0.0001" ixy="0" ixz="0" iyy="0.0001" iyz="0" izz="0.0001"/>
        </inertial>
        <visual>
            <origin rpy="0 0 0" xyz="0 0 0"/>
            <geometry>
                <box size="0.001 0.001 0.001"/>
            </geometry>
            <!-- <material name="red"/> -->
        </visual>
        <collision>
            <origin rpy="0 0 0" xyz="0 0 0"/>
            <geometry>
                <box size=".001 .001 .001"/>
            </geometry>
        </collision>
    </link>

    <xacro:leg name="FR" mirror="-1" mirror_dae= "False" front_hind="1"  front_hind_dae="True"  />
    <xacro:leg name="FL" mirror="1"  mirror_dae="True"   front_hind="1"  front_hind_dae="True"  />
    <xacro:leg name="RR" mirror="-1" mirror_dae="False"  front_hind="-1" front_hind_dae="False" />
    <xacro:leg name="RL" mirror="1"  mirror_dae="True"   front_hind="-1" front_hind_dae="False" />

    <xacro:depthCamera camID="1" name="face">
        <origin rpy="${PI} 0 0" xyz="0.2785 0.0125 0.0167"/>
    </xacro:depthCamera>
<!-- COMMENTED OUT TO TRY AND UPDATE REFRESH RATE, ALSO ONLY USING DEPTHCAMERA1 AND COMMENTING OUT ULTRASOUND AND -->
<!--
    <xacro:depthCamera camID="2" name="chin">
        <origin rpy="${PI} ${PI/2} 0" xyz="0.2522 0.0125 -0.0436"/>
    </xacro:depthCamera>

    <xacro:depthCamera camID="3" name="left">
        <origin rpy="${PI} 0.2618 ${PI/2}" xyz="-0.066 0.082 -0.0176"/>
    </xacro:depthCamera>

    <xacro:depthCamera camID="4" name="right">
        <origin rpy="${PI} 0.2618 ${-PI/2}" xyz="-0.041 -0.082 -0.0176"/>
    </xacro:depthCamera>

    <xacro:depthCamera camID="5" name="rearDown">
        <origin rpy="${PI} ${PI/2} 0" xyz="-0.0825 0.0125 -0.04365"/>
    </xacro:depthCamera>

    <joint name="camera_laserscan_joint_left" type="fixed">
        <origin rpy="0 0.2618 0" xyz="0 0 0"/>
        <parent link="camera_left"/>
        <child link="camera_laserscan_link_left"/>
    </joint>

    <link name="camera_laserscan_link_left">
    </link>

    <joint name="camera_laserscan_joint_right" type="fixed">
        <origin rpy="0 0.2618 0" xyz="0 0 0"/>
        <parent link="camera_right"/>
        <child link="camera_laserscan_link_right"/>
    </joint>

    <link name="camera_laserscan_link_right">
    </link>

    <xacro:ultraSound name="left">
        <origin rpy="0 0.2618 ${PI/2}" xyz="-0.0535  0.0826 0.00868"/>
    </xacro:ultraSound>

    <xacro:ultraSound name="right">
        <origin rpy="0 0.2618 ${-PI/2}" xyz="-0.0535 -0.0826 0.00868"/>
    </xacro:ultraSound>

    <xacro:ultraSound name="face">
        <origin rpy="0 0 0" xyz="0.2747 0.0 -0.0088"/>
    </xacro:ultraSound>
-->    
</robot>
